2023-08-15 16:38:22,482 - instabot version: 0.117.0 (bot) - INFO - Instabot version: 0.117.0 Started
2023-08-15 16:38:22,482 - instabot version: 0.117.0 (bot) - DEBUG - Bot imported from /home/pmc/.local/lib/python3.10/site-packages/instabot/bot/bot.py
2023-08-15 16:38:22,483 - instabot version: 0.117.0 (api_login) - INFO - Not yet logged in starting: PRE-LOGIN FLOW!
2023-08-15 16:38:22,903 - instabot version: 0.117.0 (api) - DEBUG - POST to endpoint: accounts/get_prefill_candidates/ returned response: <Response [429]>
2023-08-15 16:38:22,903 - instabot version: 0.117.0 (api) - DEBUG - Responsecode indicates error; response content: b'{"message":"Please wait a few minutes before you try again.","status":"fail"}'
2023-08-15 16:38:22,903 - instabot version: 0.117.0 (api) - ERROR - Request returns 429 error!
2023-08-15 16:38:22,903 - instabot version: 0.117.0 (api) - WARNING - That means 'too many requests'. I'll go to sleep for 5 minutes.
2023-08-15 16:43:23,002 - instabot version: 0.117.0 (api) - WARNING - HTTPSConnectionPool(host='i.instagram.com', port=443): Max retries exceeded with url: /api/v1/accounts/get_prefill_candidates/ (Caused by NewConnectionError('<urllib3.connection.HTTPSConnection object at 0x7f348a1aacb0>: Failed to establish a new connection: [Errno -2] Name or service not known'))
2023-08-15 16:43:23,006 - instabot version: 0.117.0 (api) - WARNING - HTTPSConnectionPool(host='i.instagram.com', port=443): Max retries exceeded with url: /api/v1/qe/sync/ (Caused by NewConnectionError('<urllib3.connection.HTTPSConnection object at 0x7f348a1ab340>: Failed to establish a new connection: [Errno -2] Name or service not known'))
2023-08-15 16:43:23,008 - instabot version: 0.117.0 (api) - WARNING - HTTPSConnectionPool(host='i.instagram.com', port=443): Max retries exceeded with url: /api/v1/launcher/sync/ (Caused by NewConnectionError('<urllib3.connection.HTTPSConnection object at 0x7f348a1aa320>: Failed to establish a new connection: [Errno -2] Name or service not known'))
2023-08-15 16:43:23,010 - instabot version: 0.117.0 (api) - WARNING - HTTPSConnectionPool(host='i.instagram.com', port=443): Max retries exceeded with url: /api/v1/accounts/contact_point_prefill/ (Caused by NewConnectionError('<urllib3.connection.HTTPSConnection object at 0x7f348a1aacb0>: Failed to establish a new connection: [Errno -2] Name or service not known'))
